<?xml version="1.0"?>
<robot name="sentry_robot" xmlns:xacro="http://ros.org/wiki/xacro">
  
    <!-- Define robot constants (that we arent using)-->
  <xacro:property name="base_width" value="0.495"/>
  <xacro:property name="base_length" value="0.495"/>
  <xacro:property name="base_height" value="0.15"/>
  <xacro:property name="ground_offset" value="0.05"/>

  <xacro:property name="wheel_radius" value="0.1"/>
  <xacro:property name="wheel_width" value="0.05"/>
  <xacro:property name="wheel_mass" value="0.5"/>

  <xacro:property name="gimbal_radius" value="0.05"/>
  <xacro:property name="gimbal_height" value="0.1"/>

  <xacro:property name="lidar_length" value="0.054"/>
  <xacro:property name="lidar_width" value="0.04629"/>
  <xacro:property name="lidar_height" value="0.0348"/>

  <xacro:property name="support_width" value="0.05"/>
  <xacro:property name="support_length" value="0.1"/>
  <xacro:property name="support_base_height" value="0.075"/>
  <xacro:property name="support_standoff_height" value="0.25"/>

  <xacro:property name="turret_shaft_radius" value="0.01"/>

  <xacro:property name="turret_length" value="0.15"/>
  <xacro:property name="turret_height" value="0.075"/>


  <xacro:property name="mass" value="20"/>

  <!-- Define inertial property macros  -->
  <xacro:macro name="box_inertia" params="m w h d">
  <inertial>
    <origin xyz="0 0 0" rpy="0 0 0"/>
    <mass value="${m}"/>
    <inertia
      ixx="${(m/12) * (h*h + d*d)}"
      ixy="0"
      ixz="0"
      iyy="${(m/12) * (w*w + d*d)}"
      iyz="0"
      izz="${(m/12) * (w*w + h*h)}"/>
  </inertial>
</xacro:macro>


  <xacro:macro name="cylinder_inertia" params="m rad h">
  <inertial>
    <origin xyz="0 0 0" rpy="0 0 0"/>
    <mass value="${m}"/>
    <inertia
      ixx="${(m/12) * (3*rad*rad + h*h)}"
      ixy="0"
      ixz="0"
      iyy="${(m/12) * (3*rad*rad + h*h)}"
      iyz="0"
      izz="${(m/2) * (rad*rad)}"/>
  </inertial>
</xacro:macro>


  <!-- Base Link -->
  <link name="base_link">
    <origin xyz="0 0 ${base_height/2 + ground_offset}" rpy="0 0 0"/>
    <visual>
      <origin xyz="0 0 ${base_height/2 + ground_offset}" rpy="0 0 0"/>
      <geometry>
        <box size="${base_width} ${base_length} ${base_height}"/>
      </geometry>
      <material name="blue">
        <color rgba="0 0 0.8 1"/>
      </material>
    </visual>
    <collision>
      <origin xyz="0 0 ${base_height/2 + ground_offset}" rpy="0 0 0"/>
      <geometry>
        <box size="${base_width} ${base_length} ${base_height}"/>
      </geometry>
    </collision>
    <xacro:box_inertia m="${mass}" w="${base_width}" d="${base_length}" h="${base_height}"/>
  </link>
  
  <!-- Front Left Wheel -->
  <link name="front_left_wheel">
    <visual>
      <geometry>
        <cylinder radius="${wheel_radius}" length="${wheel_width}"/>
      </geometry>
      <origin xyz="0 0 0" rpy="0 0 0"/>
      <material name="black">
        <color rgba="0 0 0 1"/>
      </material>
    </visual>
    <collision>
      <geometry>
        <cylinder radius="${wheel_radius}" length="${wheel_width}"/>
      </geometry>
      <origin xyz="0 0 0" rpy="0 0 0"/>
    </collision>
    <xacro:cylinder_inertia m="${wheel_mass}" rad="${wheel_radius}" h="${wheel_width}"/>
  </link>
  
  <joint name="front_left_wheel_joint" type="continuous">
    <parent link="base_link"/>
    <child link="front_left_wheel"/>
    <origin xyz="${base_width/2 + wheel_width/2} ${base_length/2 + wheel_width/2} ${wheel_radius}" rpy="0 1.5708 0"/>
    <dynamics damping="0.1" friction="0.1"/>
    <axis xyz="0 0 1"/>
  </joint>
  
  <!-- Front Right Wheel -->
  <link name="front_right_wheel">
    <visual>
      <geometry>
        <cylinder radius="${wheel_radius}" length="${wheel_width}"/>
      </geometry>
      <origin xyz="0 0 0" rpy="0 0 0"/>
      <material name="black">
        <color rgba="0 0 0 1"/>
      </material>
    </visual>
    <collision>
      <geometry>
        <cylinder radius="${wheel_radius}" length="${wheel_width}"/>
      </geometry>
      <origin xyz="0 0 0" rpy="0 0 0"/>
    </collision>
    <xacro:cylinder_inertia m="${wheel_mass}" rad="${wheel_radius}" h="${wheel_width}"/>
  </link>
  
  <joint name="front_right_wheel_joint" type="continuous">
    <parent link="base_link"/>
    <child link="front_right_wheel"/>
    <origin xyz="${-1 * base_width/2 - wheel_width/2} ${base_length/2 + wheel_width/2} ${wheel_radius}" rpy="0 1.5708 0"/>
    <dynamics damping="0.1" friction="0.1"/>
    <axis xyz="0 0 1"/>
  </joint>
  
  <!-- Back Left Wheel -->
  <link name="back_left_wheel">
    <visual>
      <geometry>
        <cylinder radius="${wheel_radius}" length="${wheel_width}"/>
      </geometry>
      <origin xyz="0 0 0" rpy="0 0 0"/>
      <material name="black">
        <color rgba="0 0 0 1"/>
      </material>
    </visual>
    <collision>
      <geometry>
        <cylinder radius="${wheel_radius}" length="${wheel_width}"/>
      </geometry>
      <origin xyz="0 0 0" rpy="0 0 0"/>
    </collision>
    <xacro:cylinder_inertia m="${wheel_mass}" rad="${wheel_radius}" h="${wheel_width}"/>
  </link>
  
  <joint name="back_left_wheel_joint" type="continuous">
    <parent link="base_link"/>
    <child link="back_left_wheel"/>
    <origin xyz="${base_width/2 + wheel_width/2} ${-1*base_length/2 - wheel_width/2} ${wheel_radius}" rpy="0 1.5708 0"/>
    <dynamics damping="0.1" friction="0.1"/>
    <axis xyz="0 0 1"/>
  </joint>
  
  <!-- Back Right Wheel -->
  <link name="back_right_wheel">
    <visual>
    <origin xyz="0 0 0" rpy="0 0 0"/>
      <geometry>
        <cylinder radius="${wheel_radius}" length="${wheel_width}"/>
      </geometry>
      <material name="black">
        <color rgba="0 0 0 1"/>
      </material>
    </visual>
    <collision>
    <origin xyz="0 0 0" rpy="0 0 0"/>
      <geometry>
        <cylinder radius="${wheel_radius}" length="${wheel_width}"/>
      </geometry>
    </collision>
    <xacro:cylinder_inertia m="${wheel_mass}" rad="${wheel_radius}" h="${wheel_width}"/>
  </link>
  
  <joint name="back_right_wheel_joint" type="continuous">
    <parent link="base_link"/>
    <child link="back_right_wheel"/>
    <origin xyz="${-1 * base_width/2 - wheel_width/2} ${-1*base_length/2 - wheel_width/2} ${wheel_radius}" rpy="0 1.5708 0"/>
    <dynamics damping="0.1" friction="0.1"/>
    <axis xyz="0 0 1"/>
  </joint>
  
   <link name="gimbal_link">
    <visual>
      <origin xyz="0 0 0" rpy="0 0 0"/>
      <geometry>
        <cylinder radius="${gimbal_radius}" length="${gimbal_height}"/>
      </geometry>
      <material name="Cyan">
        <color rgba="0 1.0 1.0 1.0"/>
      </material>
    </visual>
      <collision>
        <origin xyz="0 0 0" rpy="0 0 0"/>
        <geometry>
          <cylinder radius="${gimbal_radius}" length="${gimbal_height}"/>
        </geometry>
      </collision>
      <xacro:cylinder_inertia m="0.5" rad="${gimbal_radius}" h="${gimbal_height}"/>
  </link>

  <joint name="gimbal_joint" type="continuous">
      <parent link="base_link"/>
      <child link="gimbal_link"/>
      <origin xyz="0 0 ${base_height + ground_offset + gimbal_height/2}" rpy="0 0 0"/>
      <axis xyz="0 0 1"/>
  </joint>


   <!-- support_base -->
  <link name="bottom_support_link">
    <visual>
      <origin xyz="0 0 0" rpy="0 0 0"/>
      <geometry>
        <box size="${support_width * 2 + 2 * gimbal_radius} ${support_length} ${support_base_height}"/>
      </geometry>
      <material name="red">
        <color rgba="1 0 0 1"/>
      </material>
    </visual>
    <collision>
      <origin xyz="0 0 0" rpy="0 0 0"/>
      <geometry>
        <box size="${support_width * 2 + 2 * gimbal_radius} ${support_length} ${support_base_height}"/>
      </geometry>
    </collision>
    <xacro:box_inertia m="${0.5}" w="${support_width * 2 + 2 * gimbal_radius}" d="${support_length}" h="${support_base_height}"/>
  </link>

   <joint name="bottom_support_joint" type="fixed">
      <parent link="gimbal_link"/>
      <child link="bottom_support_link"/>
      <origin xyz="0 0 ${support_base_height / 2}" rpy="0 0 0"/>
  </joint>

  <!-- LSL -->
  <link name="left_support_link">
    <visual>
      <origin xyz="0 0 0" rpy="0 0 0"/>
      <geometry>
        <box size="${support_width} ${support_length} ${support_standoff_height}"/>
      </geometry>
      <material name="red">
        <color rgba="1 0 0 1"/>
      </material>
    </visual>
    <collision>
      <origin xyz="0 0 0" rpy="0 0 0"/>
      <geometry>
        <box size="${support_width} ${support_length} ${support_standoff_height}"/>
      </geometry>
    </collision>
    <xacro:box_inertia m="${0.5}" w="${support_width}" d="${support_length}" h="${support_standoff_height}"/>
  </link>

   <joint name="left_support_joint" type="fixed">
      <parent link="bottom_support_link"/>
      <child link="left_support_link"/>
      <origin xyz="${1.5 * support_width + gimbal_radius} 0 ${(support_standoff_height - support_base_height)/2}" rpy="0 0 0"/>
  </joint>

  <!-- RSL -->
  <link name="right_support_link">
    <visual>
      <origin xyz="0 0 0" rpy="0 0 0"/>
      <geometry>
        <box size="${support_width} ${support_length} ${support_standoff_height}"/>
      </geometry>
      <material name="red">
        <color rgba="1 0 0 1"/>
      </material>
    </visual>
    <collision>
      <origin xyz="0 0 0" rpy="0 0 0"/>
      <geometry>
        <box size="${support_width} ${support_length} ${support_standoff_height}"/>
      </geometry>
    </collision>
    <xacro:box_inertia m="${0.5}" w="${support_width}" d="${support_length}" h="${support_standoff_height}"/>
  </link>

   <joint name="right_support_joint" type="fixed">
      <parent link="bottom_support_link"/>
      <child link="right_support_link"/>
      <origin xyz="${-(1.5 * support_width + gimbal_radius)} 0 ${(support_standoff_height - support_base_height)/2}" rpy="0 0 0"/>
  </joint>

  <!-- Turret shaft -->
  <link name="turret_shaft_link">
    <visual>
    <origin xyz="0 0 0" rpy="0 0 0"/>
      <geometry>
        <cylinder radius="${turret_shaft_radius}" length="${2*(support_width + gimbal_radius)}"/>
      </geometry>
      <material name="yellow">
        <color rgba="0 1 0 1"/>
      </material>
    </visual>
    <xacro:cylinder_inertia m="${0.5}" rad="${turret_shaft_radius}" h="${2*(support_width + gimbal_radius)}"/>
  </link>
  
  <joint name="turret_shaft_joint" type="revolute">
    <parent link="bottom_support_link"/>
    <child link="turret_shaft_link"/>
    <origin xyz="0 0 ${0.75 * support_standoff_height}" rpy="0 1.5708 0"/>
    <axis xyz="0 0 1"/>
      <limit lower="-0.784" upper="0.784" effort="5" velocity="3.14"/> <!--not sure good values here-->
  </joint>

  <!-- Turret box -->
  <link name="turret_link">
    <visual>
      <origin xyz="0 0 0" rpy="0 0 0"/>
      <geometry>
        <box size="${2*(support_width + gimbal_radius)} ${turret_length} ${turret_height}"/>
      </geometry>
      <material name="green">
        <color rgba="1 1 0 1"/>
      </material>
    </visual>
    <collision>
      <origin xyz="0 0 0" rpy="0 0 0"/>
      <geometry>
        <box size="${2*(support_width + gimbal_radius)} ${turret_length} ${turret_height}"/>
      </geometry>
    </collision>
    <xacro:box_inertia m="3" w="${2*(support_width + gimbal_radius)}" d="${turret_length}" h="${turret_height}"/>
  </link>

   <joint name="turret_joint" type="fixed">
      <parent link="turret_shaft_link"/>
      <child link="turret_link"/>
      <origin xyz="0 -0.02 0" rpy="1.5708 0 1.5708"/>
  </joint>

  <!-- gun barrel shaft -->
  <link name="gun_shaft_link">
    <visual>
    <origin xyz="0 0 0" rpy="0 0 0"/>
      <geometry>
        <cylinder radius="0.02" length="0.15"/>
      </geometry>
      <material name="something">
        <color rgba="0 1 1 1"/>
      </material>
    </visual>
  </link>
  
  <joint name="gun_shaft_joint" type="fixed">
    <parent link="turret_link"/>
    <child link="gun_shaft_link"/>
    <origin xyz="${turret_length/2 + 0.025} 0 0" rpy="0 1.5708 0"/>
    <axis xyz="0 0 1"/>
  </joint>
  

  <!-- LiDAR -->
  <link name="laser_frame">
    <visual>
      <geometry>
        <cylinder radius="0.03" length="0.04"/>
      </geometry>
      <material name="purple">
        <color rgba="1 0 1 1"/>
      </material>
    </visual>
    <collision>
      <geometry>
        <cylinder radius="0.03" length="0.04"/>
      </geometry>
    </collision>
    <inertial>
      <mass value="0.1"/>
      <origin xyz="0 0 0" rpy="0 0 0"/>
      <inertia ixx="0.0001" ixy="0.0" ixz="0.0" 
               iyy="0.0001" iyz="0.0" izz="0.0001"/>
    </inertial>
  </link>
  
  <joint name="laser_joint" type="fixed">
    <parent link="left_support_link"/>
    <child link="laser_frame"/>
    <origin xyz="0 0 ${support_standoff_height / 2 + 0.02}" rpy="0 0 0"/>
  </joint>
  
  <!-- IMU -->
  <link name="imu_link">
    <visual>
      <geometry>
        <box size="0.02 0.02 0.01"/>
      </geometry>
      <material name="green">
        <color rgba="0 1 0 1"/>
      </material>
    </visual>
    <inertial>
      <mass value="0.01"/>
      <origin xyz="0 0 0" rpy="0 0 0"/>
      <inertia ixx="0.00001" ixy="0.0" ixz="0.0" 
               iyy="0.00001" iyz="0.0" izz="0.00001"/>
    </inertial>
  </link>
  
  <joint name="imu_joint" type="fixed">
    <parent link="base_link"/>
    <child link="imu_link"/>
    <origin xyz="0 0 0.1" rpy="0 0 0"/>
  </joint>
  
  <!-- depth camera-->
  <link name="depth_camera_link">
  <visual>
    <geometry>
      <box size="0.05 0.05 0.05"/>
    </geometry>
  </visual>

  <collision>
    <geometry>
      <box size="0.05 0.05 0.05"/>
    </geometry>
  </collision>

  <inertial>
    <mass value="0.05"/>
    <inertia
      ixx="1e-5" ixy="0" ixz="0"
      iyy="1e-5" iyz="0"
      izz="1e-5"/>
  </inertial>
  </link>

  <joint name="depth_camera_joint" type="fixed">
  <parent link="turret_link"/>
  <child link="depth_camera_link"/>
  <origin xyz="0.05 0 ${-1 * (turret_height / 2  + 0.025)}" rpy="0 0 0"/>
  </joint>


    <!-- Gazebo-specific properties for base_link -->
    <gazebo reference="base_link">
    <mu1>0.2</mu1>
    <mu2>0.2</mu2>
    <kp>1000000.0</kp>
    <kd>100.0</kd>
    <minDepth>0.001</minDepth>
    <maxVel>1.0</maxVel>
    </gazebo>

    <!-- Gazebo-specific properties for wheels -->
    <gazebo reference="front_left_wheel">
        <mu1>1.0</mu1>
        <mu2>1.0</mu2>
        <kp>1000000.0</kp>
        <kd>1.0</kd>
        <minDepth>0.001</minDepth>
        <material>Gazebo/Black</material>
    </gazebo>

    <gazebo reference="front_right_wheel">
        <mu1>1.0</mu1>
        <mu2>1.0</mu2>
        <kp>1000000.0</kp>
        <kd>1.0</kd>
        <minDepth>0.001</minDepth>
        <material>Gazebo/Black</material>
    </gazebo>

    <gazebo reference="back_left_wheel">
        <mu1>1.0</mu1>
        <mu2>1.0</mu2>
        <kp>1000000.0</kp>
        <kd>1.0</kd>
        <minDepth>0.001</minDepth>
        <material>Gazebo/Black</material>
    </gazebo>

    <gazebo reference="back_right_wheel">
        <mu1>1.0</mu1>
        <mu2>1.0</mu2>
        <kp>1000000.0</kp>
        <kd>1.0</kd>
        <minDepth>0.001</minDepth>
        <material>Gazebo/Black</material>
    </gazebo>

<!-- Gazebo Planar Move Plugin (for omnidirectional motion) -->
  <gazebo>
    <plugin name="planar_move" filename="libgazebo_ros_planar_move.so">
      <update_rate>50</update_rate>
      <publish_rate>50</publish_rate>
      <publish_odom>true</publish_odom>
      <publish_odom_tf>true</publish_odom_tf>
      <odometry_frame>odom</odometry_frame>
      <robot_base_frame>base_link</robot_base_frame>
      <cmd_vel_topic>cmd_vel</cmd_vel_topic>
      <odometry_topic>odom</odometry_topic>
      <covariance_x>0.0001</covariance_x>
      <covariance_y>0.0001</covariance_y>
      <covariance_yaw>0.01</covariance_yaw>
    </plugin>
  </gazebo>
  
  <!-- Joint State Publisher Plugin (publishes wheel joint states) -->
  <gazebo>
    <plugin name="gazebo_ros_joint_state_publisher" filename="libgazebo_ros_joint_state_publisher.so">
      <update_rate>50</update_rate>
      <joint_name>front_left_wheel_joint</joint_name>
      <joint_name>front_right_wheel_joint</joint_name>
      <joint_name>back_left_wheel_joint</joint_name>
      <joint_name>back_right_wheel_joint</joint_name>
    </plugin>
  </gazebo>

  <!-- LiDAR Plugin -->
  <gazebo reference="laser_frame">
    <sensor name="laser" type="ray">
      <pose>0 0 0 0 0 0</pose>
      <visualize>true</visualize>
      <update_rate>10</update_rate>
      <ray>
        <scan>
          <horizontal>
            <samples>360</samples>
            <resolution>1</resolution>
            <min_angle>-3.14159</min_angle>
            <max_angle>3.14159</max_angle>
          </horizontal>
        </scan>
        <range>
          <min>0.1</min>
          <max>10.0</max>
          <resolution>0.01</resolution>
        </range>
      </ray>
      <plugin name="laser_controller" filename="libgazebo_ros_ray_sensor.so">
        <ros>
          <remapping>~/out:=scan</remapping>
        </ros>
        <output_type>sensor_msgs/LaserScan</output_type>
        <frame_name>laser_frame</frame_name>
      </plugin>
    </sensor>
  </gazebo>
  
  <!-- IMU Plugin -->
  <gazebo reference="imu_link">
    <gravity>true</gravity>
    <sensor name="imu_sensor" type="imu">
      <always_on>true</always_on>
      <update_rate>50</update_rate>
      <plugin filename="libgazebo_ros_imu_sensor.so" name="imu_plugin">
        <ros>
          <remapping>~/out:=imu</remapping>
        </ros>
        <initial_orientation_as_reference>false</initial_orientation_as_reference>
      </plugin>
    </sensor>
  </gazebo>

  <!-- Depth camera Plugin -->
  <gazebo reference="depth_camera_link">
  <sensor type="depth" name="depth_camera">
    <update_rate>30</update_rate>

    <camera>
      <horizontal_fov>1.047</horizontal_fov> <!-- 60 deg -->

      <image>
        <width>640</width>
        <height>480</height>
        <format>R8G8B8</format>
      </image>

      <clip>
        <near>0.1</near>
        <far>10.0</far>
      </clip>
    </camera>

    <plugin name="depth_camera_controller" filename="libgazebo_ros_depth_camera.so">
      <ros>
        <namespace>/sentry</namespace>
      </ros>

      <frame_name>depth_camera_link</frame_name>

      <image_topic_name>image_raw</image_topic_name>
      <depth_image_topic_name>depth/image_raw</depth_image_topic_name>
      <camera_info_topic_name>camera_info</camera_info_topic_name>

      <point_cloud>true</point_cloud>
      <point_cloud_topic_name>points</point_cloud_topic_name>
    </plugin>
  </sensor>
</gazebo>

</robot>