<?xml version="1.0"?>
<robot name="sentry" xmlns:xacro="http://ros.org/wiki/xacro">
  <!-- Define robot constants -->
  <xacro:property name="base_width" value="0.31"/>
  <xacro:property name="base_length" value="0.42"/>
  <xacro:property name="base_height" value="0.18"/>

  <xacro:property name="wheel_radius" value="0.10"/>
  <xacro:property name="wheel_width" value="0.04"/>
  <xacro:property name="wheel_ygap" value="0.025"/>
  <xacro:property name="wheel_zoff" value="0.05"/>
  <xacro:property name="wheel_xoff" value="0.12"/>

  <xacro:property name="gimbal_radius" value="0.05"/>
  <xacro:property name="gimbal_height" value="0.09"/>

  <!-- Define inertial property macros  -->
  <xacro:macro name="box_inertia" params="m w h d">
    <inertial>
      <origin xyz="0 0 0" rpy="${pi/2} 0 ${pi/2}"/>
      <mass value="${m}"/>
      <inertia ixx="${(m/12) * (h*h + d*d)}" ixy="0.0" ixz="0.0" iyy="${(m/12) * (w*w + d*d)}" iyz="0.0" izz="${(m/12) * (w*w + h*h)}"/>
    </inertial>
  </xacro:macro>

  <xacro:macro name="cylinder_inertia" params="m r h">
    <inertial>
      <origin xyz="0 0 0" rpy="${pi/2} 0 0" />
      <mass value="${m}"/>
      <inertia ixx="${(m/12) * (3*r*r + h*h)}" ixy = "0" ixz = "0" iyy="${(m/12) * (3*r*r + h*h)}" iyz = "0" izz="${(m/2) * (r*r)}"/>
    </inertial>
  </xacro:macro>

  

  <!--Sentry Base -->
  <link name="base_link">
    <visual>
      <geometry>
        <box size="${base_length} ${base_width} ${base_height}"/>
      </geometry>
      <material name="Cyan">
        <color rgba="0 1.0 1.0 1.0"/>
      </material>
    </visual>

    <collision>
      <geometry>
        <box size="${base_length} ${base_width} ${base_height}"/>
      </geometry>
    </collision>

  </link>

  <!-- Robot Footprint -->
  <link name="base_footprint">

    <!-- Inertial property-->
    <xacro:box_inertia m="15" w="${base_width}" d="${base_length}" h="${base_height}"/>

  </link>

  <joint name="base_joint" type="fixed">
    <parent link="base_link"/>
    <child link="base_footprint"/>
    <origin xyz="0.0 0.0 ${-(wheel_radius+wheel_zoff)}" rpy="0 0 0"/>
  </joint>

<!-- Wheels Macro with optional mimic joint -->
<xacro:macro name="wheel" params="prefix x_reflect y_reflect mimic_joint">
  <link name="${prefix}_link">
    <visual>
      <origin xyz="0 0 0" rpy="${pi/2} 0 0"/>
      <geometry>
        <cylinder radius="${wheel_radius}" length="${wheel_width}"/>
      </geometry>
      <material name="Gray">
        <color rgba="0.5 0.5 0.5 1.0"/>
      </material>
    </visual>

    <collision>
      <origin xyz="0 0 0" rpy="${pi/2} 0 0"/>
      <geometry>
        <cylinder radius="${wheel_radius}" length="${wheel_width}"/>
      </geometry>
    </collision>

    <xacro:cylinder_inertia m="0.5" r="${wheel_radius}" h="${wheel_width}"/>
  </link>

  <joint name="${prefix}_joint" type="continuous">
    <parent link="base_link"/>
    <child link="${prefix}_link"/>
    <origin xyz="${x_reflect*wheel_xoff} ${y_reflect*(base_width/2+wheel_ygap)} ${-wheel_zoff}" rpy="0 0 0"/>
    <axis xyz="0 1 0"/>
    <xacro:if value="${mimic_joint != ''}">
      <mimic joint="${mimic_joint}" multiplier="1"/>
    </xacro:if>
  </joint>
</xacro:macro>

<!-- Instantiate wheels -->
<!-- Back wheels: control odometry -->
<xacro:wheel prefix="drivewhl_bl" x_reflect="-1" y_reflect="1" mimic_joint=""/>
<xacro:wheel prefix="drivewhl_br" x_reflect="-1" y_reflect="-1" mimic_joint=""/>

<!-- Front wheels: mimic back wheels -->
<xacro:wheel prefix="drivewhl_fl" x_reflect="1" y_reflect="1" mimic_joint="drivewhl_bl_joint"/>
<xacro:wheel prefix="drivewhl_fr" x_reflect="1" y_reflect="-1" mimic_joint="drivewhl_br_joint"/>


  <link name="gimbal_link">
    <visual>
        <origin xyz="0 0 0" rpy="0 0 0"/>
      <geometry>
        <cylinder radius="${gimbal_radius}" length="${gimbal_height}"/>
      </geometry>
      <material name="Cyan">
        <color rgba="0 1.0 1.0 1.0"/>
      </material>
    </visual>

    <!-- Collision box-->
      <collision>
        <origin xyz="0 0 0" rpy="0 0 0"/>
        <geometry>
          <cylinder radius="${gimbal_radius}" length="${gimbal_height}"/>
        </geometry>
      </collision>

      <xacro:cylinder_inertia m="0.5" r="${gimbal_radius}" h="${gimbal_height}"/>
  </link>

  <joint name="gimbal_joint" type="continuous">
      <parent link="base_link"/>
      <child link="gimbal_link"/>
      <origin xyz="0 0 ${base_height/2 + gimbal_height/2}" rpy="0 0 0"/>
      <axis xyz="0 0 1"/>
  </joint>

  
  <link name="imu_link">
  <visual>
    <geometry>
      <box size="0.1 0.1 0.1"/>
    </geometry>
  </visual>

  <collision>
    <geometry>
      <box size="0.1 0.1 0.1"/>
    </geometry>
  </collision>

  <xacro:box_inertia m="0.1" w="0.1" d="0.1" h="0.1"/>
</link>

<joint name="imu_joint" type="fixed">
  <parent link="base_link"/>
  <child link="imu_link"/>
  <origin xyz="0 0 0.01"/>
</joint>


<!-- IMU Sensor data (unchanged from nav2 tutorial)-->
 <gazebo reference="imu_link">
  <sensor name="imu_sensor" type="imu">
   <plugin filename="libgazebo_ros_imu_sensor.so" name="imu_plugin">
      <ros>
        <namespace>/demo</namespace>
        <remapping>~/out:=imu</remapping>
      </ros>
      <initial_orientation_as_reference>false</initial_orientation_as_reference>
    </plugin>
    <always_on>true</always_on>
    <update_rate>100</update_rate>
    <visualize>true</visualize>
    <imu>
      <angular_velocity>
        <x>
          <noise type="gaussian">
            <mean>0.0</mean>
            <stddev>2e-4</stddev>
            <bias_mean>0.0000075</bias_mean>
            <bias_stddev>0.0000008</bias_stddev>
          </noise>
        </x>
        <y>
          <noise type="gaussian">
            <mean>0.0</mean>
            <stddev>2e-4</stddev>
            <bias_mean>0.0000075</bias_mean>
            <bias_stddev>0.0000008</bias_stddev>
          </noise>
        </y>
        <z>
          <noise type="gaussian">
            <mean>0.0</mean>
            <stddev>2e-4</stddev>
            <bias_mean>0.0000075</bias_mean>
            <bias_stddev>0.0000008</bias_stddev>
          </noise>
        </z>
      </angular_velocity>
      <linear_acceleration>
        <x>
          <noise type="gaussian">
            <mean>0.0</mean>
            <stddev>1.7e-2</stddev>
            <bias_mean>0.1</bias_mean>
            <bias_stddev>0.001</bias_stddev>
          </noise>
        </x>
        <y>
          <noise type="gaussian">
            <mean>0.0</mean>
            <stddev>1.7e-2</stddev>
            <bias_mean>0.1</bias_mean>
            <bias_stddev>0.001</bias_stddev>
          </noise>
        </y>
        <z>
          <noise type="gaussian">
            <mean>0.0</mean>
            <stddev>1.7e-2</stddev>
            <bias_mean>0.1</bias_mean>
            <bias_stddev>0.001</bias_stddev>
          </noise>
        </z>
      </linear_acceleration>
    </imu>
  </sensor>
</gazebo>

<gazebo>
  <plugin name='diff_drive' filename='libgazebo_ros_diff_drive.so'>
    <ros>
      <namespace>/demo</namespace>
    </ros>

    <!-- wheels -->
    <left_joint>drivewhl_bl_joint</left_joint>
    <right_joint>drivewhl_br_joint</right_joint>

    <!-- kinematics -->
    <wheel_separation>${base_width + 2*wheel_ygap}</wheel_separation>
    <wheel_diameter>${wheel_radius * 2}</wheel_diameter>

    <!-- limits -->
    <max_wheel_torque>20</max_wheel_torque>
    <max_wheel_acceleration>1.0</max_wheel_acceleration>

    <!-- output -->
    <publish_odom>true</publish_odom>
    <publish_odom_tf>true</publish_odom_tf>
    <publish_wheel_tf>true</publish_wheel_tf>
    <publish_joint_states>true</publish_joint_states>


    <odometry_frame>odom</odometry_frame>
    <robot_base_frame>base_link</robot_base_frame>
  </plugin>
</gazebo>

</robot>